Workbook

Sheet Anleitung
A1: Umfrage „Paul & REZI — Das e-Rezept Jump 'n' Run“
A2: Ziel: herausfinden, ob das Spiel gefällt, was stört und ob die TI-Inhalte hängen bleiben — als Grundlage für die nächsten Verbesserungen.
A4: So läuft es
A5: 1. Direkt nach dem Spielen: Blatt „Fragebogen“ am Tablet zeigen oder ausgedruckt mitgeben (ca. 3 Minuten, anonym).
A6: 2. Antworten ins Blatt „Antworten“ übertragen: eine Zeile pro Person, gelbe Zellen, Dropdowns nutzen. Spalte „Gültig“ auf Ja setzen — nur diese Zeilen zählen.
A7: 3. Blatt „Auswertung“ rechnet sich selbst: Kennzahlen, Zustimmung je Aussage, Quiz-Trefferquote, Störfaktoren, Segmente nach Bedienung und Sprache, zwei Diagramme.
A8: 4. Freitexte (Was hat gefallen / Was ändern) im Blatt „Antworten“ lesen und von Hand in Themen bündeln; sie sind die wertvollste Quelle für konkrete Änderungen.
A10: Legende
A11: Gelb hinterlegt = ausfüllen (Blatt „Antworten“). Blaue Schrift = Eingabe. Schwarze Schrift = Formel, nicht anfassen. Zeile 3 in „Antworten“ ist ein Beispiel (Gültig = Nein) und darf überschrieben werden.
A12: Skala 1-5: 1 = stimme gar nicht zu, 5 = stimme voll zu. Weiterempfehlung 0-10 wird als NPS ausgewertet (Anteil 9-10 minus Anteil 0-6).
A13: Mehrfachnennungen (Störfaktoren) durch Semikolon trennen, Schreibweise wie in „Listen“ (die Auswertung sucht wörtlich).
A14: Quiz Q18-Q21: die Lösungen stehen im Blatt „Listen“; die Auswertung vergleicht damit.
... A20: Erstellt am 07.09.2026 für das Experience Center PwC Frankfurt.

Sheet Fragebogen
A1: Paul & REZI — Das e-Rezept Jump 'n' Run
A2: Kurzumfrage nach dem Spielen (ca. 3 Minuten). Deine Antworten sind anonym und helfen uns, das Spiel besser zu machen.
A3: Datum: ________ Erfasst von: ________ Teilnehmer-Nr.: ____
A5: A · Über dich
A6: Q1 | B6: Ich bin … | C6: Besucher:in · PwC-Mitarbeiter:in · Kunde / Partner · Gesundheitswesen · Sonstiges
A7: Q2 | B7: Altersgruppe | C7: unter 20 · 20-29 · 30-39 · 40-49 · 50-59 · 60+
A8: Q3 | B8: Wie oft spielst du Videospiele? | C8: nie · selten · monatlich · wöchentlich · täglich
A9: Q4 | B9: Mein Vorwissen zu Telematikinfrastruktur, ePA und E-Rezept vor dem Spiel | C9: 1 = keins … 5 = Experte
A10: Q5 | B10: Womit hast du gespielt? | C10: Tastatur · Arcade-Knöpfe · Touch
A11: Q6 | B11: In welcher Sprache? | C11: Deutsch · Englisch · Französisch · Spanisch · Chinesisch · Hindi
A12: Q7 | B12: Bis zu welcher Station bist du gekommen? | C12: Station 1 … 10 · Reward erreicht
A13: Q8 | B13: Wie lange hast du ungefähr gespielt? | C13: Minuten
A15: B · Spielerlebnis (1 = stimme gar nicht zu … 5 = stimme voll zu)
A16: Q9 | B16: Das Spiel hat mir Spaß gemacht. | C16: 1 · 2 · 3 · 4 · 5
A17: Q10 | B17: Die Steuerung war leicht zu verstehen. | C17: 1 · 2 · 3 · 4 · 5
A18: Q11 | B18: Der Schwierigkeitsgrad war für mich passend. | C18: 1 · 2 · 3 · 4 · 5
A19: Q12 | B19: Ich wusste immer, was ich als Nächstes tun soll. | C19: 1 · 2 · 3 · 4 · 5
A20: Q13 | B20: Die Erklärscreens vor den Stationen (Briefings) waren hilfreich. | C20: 1 · 2 · 3 · 4 · 5
A21: Q14 | B21: Die Texte waren auch ohne Vorwissen verständlich. | C21: 1 · 2 · 3 · 4 · 5
A22: Q15 | B22: Grafik und Animationen gefallen mir. | C22: 1 · 2 · 3 · 4 · 5
A23: Q16 | B23: Musik und Klänge passen zum Spiel. | C23: 1 · 2 · 3 · 4 · 5
A24: Q17 | B24: Der Schwierigkeitsgrad war … / Die Länge des Spiels war … | C24: zu leicht · genau richtig · zu schwer / zu kurz · genau richtig · zu lang
A26: C · Was hängen geblieben ist (richtig / falsch / weiß nicht)
A27: Q18 | B27: Auf der Gesundheitskarte (eGK) sind meine Rezepte gespeichert. | C27: richtig · falsch · weiß nicht
A28: Q19 | B28: Die VAU ist ein Raum, in dem im Klartext gearbeitet wird, ohne dass der Betreiber mitliest. | C28: richtig · falsch · weiß nicht
A29: Q20 | B29: Eine abgelaufene Sitzung schützt weiterhin. | C29: richtig · falsch · weiß nicht
A30: Q21 | B30: Die Verschlüsselung ersetzt die Unterschrift (Signatur) des Arztes. | C30: richtig · falsch · weiß nicht
A31: Q22 | B31: Ich habe etwas Neues über die Telematikinfrastruktur gelernt. | C31: 1 · 2 · 3 · 4 · 5
A32: Q23 | B32: Welche Station hat dir am meisten beigebracht? | C32: Station 1 … 10
A34: D · Kritik und Ideen
A35: Q24 | B35: Was hat gestört? (mehrere Antworten möglich) | C35: Steuerung träge · Zu schwer · Zu leicht · Zu viel Text · Text zu klein · Musik / Klang · Sprachfehler · Orientierung verloren · Technikproblem · Nichts gestört
A36: Q25 | B36: Was hat dir am besten gefallen? | C36: Freitext
A37: Q26 | B37: Was würdest du ändern? | C37: Freitext
A38: Q27 | B38: Wie wahrscheinlich empfiehlst du das Spiel weiter? | C38: 0 = gar nicht … 10 = auf jeden Fall
A39: Q28 | B39: Würdest du es noch einmal spielen? | C39: Ja · Vielleicht · Nein
A41: Danke! Die Antworten kommen in das Blatt „Antworten“ (eine Zeile pro Person), die Auswertung rechnet sich selbst.

Sheet Auswertung
A1: AUSWERTUNG — rechnet aus allen Zeilen mit Gültig = Ja
A2: Nichts eintragen; alle Werte sind Formeln. Freitexte (Q25/Q26) stehen im Blatt „Antworten“ und werden von Hand geclustert.
A4: Kennzahlen
A5: Gültige Antworten (n) | B5: =COUNTIF(Antworten!$D$3:$D$500,"Ja")
A6: Ø Spielzeit (min) | B6: =IFERROR(SUMIFS(Antworten!$L$3:$L$500,Antworten!$D$3:$D$500,"Ja")/COUNTIFS(Antworten!$L$3:$L$500,">=0",Antworten!$D$3:$D$500,"Ja"),"")
A7: Ø Spaß (1-5) | B7: =IFERROR(SUMIFS(Antworten!$M$3:$M$500,Antworten!$D$3:$D$500,"Ja")/COUNTIFS(Antworten!$M$3:$M$500,">=0",Antworten!$D$3:$D$500,"Ja"),"")
A8: Ø Gelernt (1-5) | B8: =IFERROR(SUMIFS(Antworten!$AA$3:$AA$500,Antworten!$D$3:$D$500,"Ja")/COUNTIFS(Antworten!$AA$3:$AA$500,">=0",Antworten!$D$3:$D$500,"Ja"),"")
A9: NPS (−100 … +100) | B9: =IFERROR(ROUND((COUNTIFS(Antworten!$AF$3:$AF$500,">=9",Antworten!$D$3:$D$500,"Ja")-COUNTIFS(Antworten!$AF$3:$AF$500,"<=6",Antworten!$D$3:$D$500,"Ja"))/COUNTIFS(Antworten!$AF$3:$AF$500,">=0",Antworten!$D$3:$D$500,"Ja")*100,0),"") | C9: NPS = Anteil 9-10 minus Anteil 0-6, in Prozentpunkten
A10: Anteil „nochmal spielen: Ja“ | B10: =IFERROR(COUNTIFS(Antworten!$AG$3:$AG$500,"Ja",Antworten!$D$3:$D$500,"Ja")/COUNTIF(Antworten!$D$3:$D$500,"Ja"),"")
A11: Anteil Reward erreicht | B11: =IFERROR(COUNTIFS(Antworten!$K$3:$K$500,"Reward erreicht",Antworten!$D$3:$D$500,"Ja")/COUNTIF(Antworten!$D$3:$D$500,"Ja"),"")
A13: Spielerlebnis (Skala 1-5)
A14: Aussage | B14: Ø | C14: Zustimmung (4-5) | D14: n | E14: 1 | F14: 2 | G14: 3 | H14: 4 | I14: 5
A15: Spaß | B15: =IFERROR(SUMIFS(Antworten!$M$3:$M$500,Antworten!$D$3:$D$500,"Ja")/COUNTIFS(Antworten!$M$3:$M$500,">=0",Antworten!$D$3:$D$500,"Ja"),"") | C15: =IFERROR(COUNTIFS(Antworten!$M$3:$M$500,">=4",Antworten!$D$3:$D$500,"Ja")/COUNTIFS(Antworten!$M$3:$M$500,">=1",Antworten!$D$3:$D$500,"Ja"),"") | D15: =COUNTIFS(Antworten!$M$3:$M$500,">=1",Antworten!$D$3:$D$500,"Ja") | E15: =COUNTIFS(Antworten!$M$3:$M$500,1,Antworten!$D$3:$D$500,"Ja") | F15: =COUNTIFS(Antworten!$M$3:$M$500,2,Antworten!$D$3:$D$500,"Ja") | G15: =COUNTIFS(Antworten!$M$3:$M$500,3,Antworten!$D$3:$D$500,"Ja") | H15: =COUNTIFS(Antworten!$M$3:$M$500,4,Antworten!$D$3:$D$500,"Ja") | I15: =COUNTIFS(Antworten!$M$3:$M$500,5,Antworten!$D$3:$D$500,"Ja")
A16: Steuerung klar | B16: =IFERROR(SUMIFS(Antworten!$N$3:$N$500,Antworten!$D$3:$D$500,"Ja")/COUNTIFS(Antworten!$N$3:$N$500,">=0",Antworten!$D$3:$D$500,"Ja"),"") | C16: =IFERROR(COUNTIFS(Antworten!$N$3:$N$500,">=4",Antworten!$D$3:$D$500,"Ja")/COUNTIFS(Antworten!$N$3:$N$500,">=1",Antworten!$D$3:$D$500,"Ja"),"") | D16: =COUNTIFS(Antworten!$N$3:$N$500,">=1",Antworten!$D$3:$D$500,"Ja") | E16: =COUNTIFS(Antworten!$N$3:$N$500,1,Antworten!$D$3:$D$500,"Ja") | F16: =COUNTIFS(Antworten!$N$3:$N$500,2,Antworten!$D$3:$D$500,"Ja") | G16: =COUNTIFS(Antworten!$N$3:$N$500,3,Antworten!$D$3:$D$500,"Ja") | H16: =COUNTIFS(Antworten!$N$3:$N$500,4,Antworten!$D$3:$D$500,"Ja") | I16: =COUNTIFS(Antworten!$N$3:$N$500,5,Antworten!$D$3:$D$500,"Ja")
A17: Schwierigkeit passend | B17: =IFERROR(SUMIFS(Antworten!$O$3:$O$500,Antworten!$D$3:$D$500,"Ja")/COUNTIFS(Antworten!$O$3:$O$500,">=0",Antworten!$D$3:$D$500,"Ja"),"") | C17: =IFERROR(COUNTIFS(Antworten!$O$3:$O$500,">=4",Antworten!$D$3:$D$500,"Ja")/COUNTIFS(Antworten!$O$3:$O$500,">=1",Antworten!$D$3:$D$500,"Ja"),"") | D17: =COUNTIFS(Antworten!$O$3:$O$500,">=1",Antworten!$D$3:$D$500,"Ja") | E17: =COUNTIFS(Antworten!$O$3:$O$500,1,Antworten!$D$3:$D$500,"Ja") | F17: =COUNTIFS(Antworten!$O$3:$O$500,2,Antworten!$D$3:$D$500,"Ja") | G17: =COUNTIFS(Antworten!$O$3:$O$500,3,Antworten!$D$3:$D$500,"Ja") | H17: =COUNTIFS(Antworten!$O$3:$O$500,4,Antworten!$D$3:$D$500,"Ja") | I17: =COUNTIFS(Antworten!$O$3:$O$500,5,Antworten!$D$3:$D$500,"Ja")
A18: Orientierung | B18: =IFERROR(SUMIFS(Antworten!$P$3:$P$500,Antworten!$D$3:$D$500,"Ja")/COUNTIFS(Antworten!$P$3:$P$500,">=0",Antworten!$D$3:$D$500,"Ja"),"") | C18: =IFERROR(COUNTIFS(Antworten!$P$3:$P$500,">=4",Antworten!$D$3:$D$500,"Ja")/COUNTIFS(Antworten!$P$3:$P$500,">=1",Antworten!$D$3:$D$500,"Ja"),"") | D18: =COUNTIFS(Antworten!$P$3:$P$500,">=1",Antworten!$D$3:$D$500,"Ja") | E18: =COUNTIFS(Antworten!$P$3:$P$500,1,Antworten!$D$3:$D$500,"Ja") | F18: =COUNTIFS(Antworten!$P$3:$P$500,2,Antworten!$D$3:$D$500,"Ja") | G18: =COUNTIFS(Antworten!$P$3:$P$500,3,Antworten!$D$3:$D$500,"Ja") | H18: =COUNTIFS(Antworten!$P$3:$P$500,4,Antworten!$D$3:$D$500,"Ja") | I18: =COUNTIFS(Antworten!$P$3:$P$500,5,Antworten!$D$3:$D$500,"Ja")
A19: Briefings hilfreich | B19: =IFERROR(SUMIFS(Antworten!$Q$3:$Q$500,Antworten!$D$3:$D$500,"Ja")/COUNTIFS(Antworten!$Q$3:$Q$500,">=0",Antworten!$D$3:$D$500,"Ja"),"") | C19: =IFERROR(COUNTIFS(Antworten!$Q$3:$Q$500,">=4",Antworten!$D$3:$D$500,"Ja")/COUNTIFS(Antworten!$Q$3:$Q$500,">=1",Antworten!$D$3:$D$500,"Ja"),"") | D19: =COUNTIFS(Antworten!$Q$3:$Q$500,">=1",Antworten!$D$3:$D$500,"Ja") | E19: =COUNTIFS(Antworten!$Q$3:$Q$500,1,Antworten!$D$3:$D$500,"Ja") | F19: =COUNTIFS(Antworten!$Q$3:$Q$500,2,Antworten!$D$3:$D$500,"Ja") | G19: =COUNTIFS(Antworten!$Q$3:$Q$500,3,Antworten!$D$3:$D$500,"Ja") | H19: =COUNTIFS(Antworten!$Q$3:$Q$500,4,Antworten!$D$3:$D$500,"Ja") | I19: =COUNTIFS(Antworten!$Q$3:$Q$500,5,Antworten!$D$3:$D$500,"Ja")
A20: Texte verständlich | B20: =IFERROR(SUMIFS(Antworten!$R$3:$R$500,Antworten!$D$3:$D$500,"Ja")/COUNTIFS(Antworten!$R$3:$R$500,">=0",Antworten!$D$3:$D$500,"Ja"),"") | C20: =IFERROR(COUNTIFS(Antworten!$R$3:$R$500,">=4",Antworten!$D$3:$D$500,"Ja")/COUNTIFS(Antworten!$R$3:$R$500,">=1",Antworten!$D$3:$D$500,"Ja"),"") | D20: =COUNTIFS(Antworten!$R$3:$R$500,">=1",Antworten!$D$3:$D$500,"Ja") | E20: =COUNTIFS(Antworten!$R$3:$R$500,1,Antworten!$D$3:$D$500,"Ja") | F20: =COUNTIFS(Antworten!$R$3:$R$500,2,Antworten!$D$3:$D$500,"Ja") | G20: =COUNTIFS(Antworten!$R$3:$R$500,3,Antworten!$D$3:$D$500,"Ja") | H20: =COUNTIFS(Antworten!$R$3:$R$500,4,Antworten!$D$3:$D$500,"Ja") | I20: =COUNTIFS(Antworten!$R$3:$R$500,5,Antworten!$D$3:$D$500,"Ja")
A21: Grafik | B21: =IFERROR(SUMIFS(Antworten!$S$3:$S$500,Antworten!$D$3:$D$500,"Ja")/COUNTIFS(Antworten!$S$3:$S$500,">=0",Antworten!$D$3:$D$500,"Ja"),"") | C21: =IFERROR(COUNTIFS(Antworten!$S$3:$S$500,">=4",Antworten!$D$3:$D$500,"Ja")/COUNTIFS(Antworten!$S$3:$S$500,">=1",Antworten!$D$3:$D$500,"Ja"),"") | D21: =COUNTIFS(Antworten!$S$3:$S$500,">=1",Antworten!$D$3:$D$500,"Ja") | E21: =COUNTIFS(Antworten!$S$3:$S$500,1,Antworten!$D$3:$D$500,"Ja") | F21: =COUNTIFS(Antworten!$S$3:$S$500,2,Antworten!$D$3:$D$500,"Ja") | G21: =COUNTIFS(Antworten!$S$3:$S$500,3,Antworten!$D$3:$D$500,"Ja") | H21: =COUNTIFS(Antworten!$S$3:$S$500,4,Antworten!$D$3:$D$500,"Ja") | I21: =COUNTIFS(Antworten!$S$3:$S$500,5,Antworten!$D$3:$D$500,"Ja")
A22: Musik/Klang | B22: =IFERROR(SUMIFS(Antworten!$T$3:$T$500,Antworten!$D$3:$D$500,"Ja")/COUNTIFS(Antworten!$T$3:$T$500,">=0",Antworten!$D$3:$D$500,"Ja"),"") | C22: =IFERROR(COUNTIFS(Antworten!$T$3:$T$500,">=4",Antworten!$D$3:$D$500,"Ja")/COUNTIFS(Antworten!$T$3:$T$500,">=1",Antworten!$D$3:$D$500,"Ja"),"") | D22: =COUNTIFS(Antworten!$T$3:$T$500,">=1",Antworten!$D$3:$D$500,"Ja") | E22: =COUNTIFS(Antworten!$T$3:$T$500,1,Antworten!$D$3:$D$500,"Ja") | F22: =COUNTIFS(Antworten!$T$3:$T$500,2,Antworten!$D$3:$D$500,"Ja") | G22: =COUNTIFS(Antworten!$T$3:$T$500,3,Antworten!$D$3:$D$500,"Ja") | H22: =COUNTIFS(Antworten!$T$3:$T$500,4,Antworten!$D$3:$D$500,"Ja") | I22: =COUNTIFS(Antworten!$T$3:$T$500,5,Antworten!$D$3:$D$500,"Ja")
A23: Etwas gelernt | B23: =IFERROR(SUMIFS(Antworten!$AA$3:$AA$500,Antworten!$D$3:$D$500,"Ja")/COUNTIFS(Antworten!$AA$3:$AA$500,">=0",Antworten!$D$3:$D$500,"Ja"),"") | C23: =IFERROR(COUNTIFS(Antworten!$AA$3:$AA$500,">=4",Antworten!$D$3:$D$500,"Ja")/COUNTIFS(Antworten!$AA$3:$AA$500,">=1",Antworten!$D$3:$D$500,"Ja"),"") | D23: =COUNTIFS(Antworten!$AA$3:$AA$500,">=1",Antworten!$D$3:$D$500,"Ja") | E23: =COUNTIFS(Antworten!$AA$3:$AA$500,1,Antworten!$D$3:$D$500,"Ja") | F23: =COUNTIFS(Antworten!$AA$3:$AA$500,2,Antworten!$D$3:$D$500,"Ja") | G23: =COUNTIFS(Antworten!$AA$3:$AA$500,3,Antworten!$D$3:$D$500,"Ja") | H23: =COUNTIFS(Antworten!$AA$3:$AA$500,4,Antworten!$D$3:$D$500,"Ja") | I23: =COUNTIFS(Antworten!$AA$3:$AA$500,5,Antworten!$D$3:$D$500,"Ja")
A24: Vorwissen (Kontext, keine Bewertung) | B24: =IFERROR(SUMIFS(Antworten!$H$3:$H$500,Antworten!$D$3:$D$500,"Ja")/COUNTIFS(Antworten!$H$3:$H$500,">=0",Antworten!$D$3:$D$500,"Ja"),"") | C24: =IFERROR(COUNTIFS(Antworten!$H$3:$H$500,">=4",Antworten!$D$3:$D$500,"Ja")/COUNTIFS(Antworten!$H$3:$H$500,">=1",Antworten!$D$3:$D$500,"Ja"),"") | D24: =COUNTIFS(Antworten!$H$3:$H$500,">=1",Antworten!$D$3:$D$500,"Ja") | E24: =COUNTIFS(Antworten!$H$3:$H$500,1,Antworten!$D$3:$D$500,"Ja") | F24: =COUNTIFS(Antworten!$H$3:$H$500,2,Antworten!$D$3:$D$500,"Ja") | G24: =COUNTIFS(Antworten!$H$3:$H$500,3,Antworten!$D$3:$D$500,"Ja") | H24: =COUNTIFS(Antworten!$H$3:$H$500,4,Antworten!$D$3:$D$500,"Ja") | I24: =COUNTIFS(Antworten!$H$3:$H$500,5,Antworten!$D$3:$D$500,"Ja")
A26: Einstufungen
A27: Frage | B27: Option | C27: Anzahl | D27: Anteil
A28: Schwierigkeit (Q17) | B28: zu leicht | C28: =COUNTIFS(Antworten!$U$3:$U$500,"zu leicht",Antworten!$D$3:$D$500,"Ja") | D28: =IFERROR(C28/COUNTIFS(Antworten!$U$3:$U$500,"<>",Antworten!$D$3:$D$500,"Ja"),"")
A29: Schwierigkeit (Q17) | B29: genau richtig | C29: =COUNTIFS(Antworten!$U$3:$U$500,"genau richtig",Antworten!$D$3:$D$500,"Ja") | D29: =IFERROR(C29/COUNTIFS(Antworten!$U$3:$U$500,"<>",Antworten!$D$3:$D$500,"Ja"),"")
A30: Schwierigkeit (Q17) | B30: zu schwer | C30: =COUNTIFS(Antworten!$U$3:$U$500,"zu schwer",Antworten!$D$3:$D$500,"Ja") | D30: =IFERROR(C30/COUNTIFS(Antworten!$U$3:$U$500,"<>",Antworten!$D$3:$D$500,"Ja"),"")
A31: Länge (Q17) | B31: zu kurz | C31: =COUNTIFS(Antworten!$V$3:$V$500,"zu kurz",Antworten!$D$3:$D$500,"Ja") | D31: =IFERROR(C31/COUNTIFS(Antworten!$V$3:$V$500,"<>",Antworten!$D$3:$D$500,"Ja"),"")
A32: Länge (Q17) | B32: genau richtig | C32: =COUNTIFS(Antworten!$V$3:$V$500,"genau richtig",Antworten!$D$3:$D$500,"Ja") | D32: =IFERROR(C32/COUNTIFS(Antworten!$V$3:$V$500,"<>",Antworten!$D$3:$D$500,"Ja"),"")
A33: Länge (Q17) | B33: zu lang | C33: =COUNTIFS(Antworten!$V$3:$V$500,"zu lang",Antworten!$D$3:$D$500,"Ja") | D33: =IFERROR(C33/COUNTIFS(Antworten!$V$3:$V$500,"<>",Antworten!$D$3:$D$500,"Ja"),"")
A34: Nochmal spielen (Q28) | B34: Ja | C34: =COUNTIFS(Antworten!$AG$3:$AG$500,"Ja",Antworten!$D$3:$D$500,"Ja") | D34: =IFERROR(C34/COUNTIFS(Antworten!$AG$3:$AG$500,"<>",Antworten!$D$3:$D$500,"Ja"),"")
A35: Nochmal spielen (Q28) | B35: Vielleicht | C35: =COUNTIFS(Antworten!$AG$3:$AG$500,"Vielleicht",Antworten!$D$3:$D$500,"Ja") | D35: =IFERROR(C35/COUNTIFS(Antworten!$AG$3:$AG$500,"<>",Antworten!$D$3:$D$500,"Ja"),"")
A36: Nochmal spielen (Q28) | B36: Nein | C36: =COUNTIFS(Antworten!$AG$3:$AG$500,"Nein",Antworten!$D$3:$D$500,"Ja") | D36: =IFERROR(C36/COUNTIFS(Antworten!$AG$3:$AG$500,"<>",Antworten!$D$3:$D$500,"Ja"),"")
A38: Lernwirkung — Quiz (Anteil richtig)
A39: Aussage | B39: Lösung | C39: richtig | D39: falsch | E39: weiß nicht | F39: Anteil richtig
A40: Q18 Auf der Gesundheitskarte (eGK) sind meine Rezepte gespeichert. | B40: =Listen!$N$4 | C40: =COUNTIFS(Antworten!$W$3:$W$500,B40,Antworten!$D$3:$D$500,"Ja") | D40: =COUNTIFS(Antworten!$W$3:$W$500,"<>"&B40,Antworten!$W$3:$W$500,"<>weiß nicht",Antworten!$W$3:$W$500,"<>",Antworten!$D$3:$D$500,"Ja") | E40: =COUNTIFS(Antworten!$W$3:$W$500,"weiß nicht",Antworten!$D$3:$D$500,"Ja") | F40: =IFERROR(C40/(C40+D40+E40),"")
A41: Q19 Die VAU ist ein Raum, in dem im Klartext gearbeitet wird, ohne dass der Betreiber mitliest. | B41: =Listen!$N$5 | C41: =COUNTIFS(Antworten!$X$3:$X$500,B41,Antworten!$D$3:$D$500,"Ja") | D41: =COUNTIFS(Antworten!$X$3:$X$500,"<>"&B41,Antworten!$X$3:$X$500,"<>weiß nicht",Antworten!$X$3:$X$500,"<>",Antworten!$D$3:$D$500,"Ja") | E41: =COUNTIFS(Antworten!$X$3:$X$500,"weiß nicht",Antworten!$D$3:$D$500,"Ja") | F41: =IFERROR(C41/(C41+D41+E41),"")
A42: Q20 Eine abgelaufene Sitzung schützt weiterhin. | B42: =Listen!$N$6 | C42: =COUNTIFS(Antworten!$Y$3:$Y$500,B42,Antworten!$D$3:$D$500,"Ja") | D42: =COUNTIFS(Antworten!$Y$3:$Y$500,"<>"&B42,Antworten!$Y$3:$Y$500,"<>weiß nicht",Antworten!$Y$3:$Y$500,"<>",Antworten!$D$3:$D$500,"Ja") | E42: =COUNTIFS(Antworten!$Y$3:$Y$500,"weiß nicht",Antworten!$D$3:$D$500,"Ja") | F42: =IFERROR(C42/(C42+D42+E42),"")
A43: Q21 Die Verschlüsselung ersetzt die Unterschrift (Signatur) des Arztes. | B43: =Listen!$N$7 | C43: =COUNTIFS(Antworten!$Z$3:$Z$500,B43,Antworten!$D$3:$D$500,"Ja") | D43: =COUNTIFS(Antworten!$Z$3:$Z$500,"<>"&B43,Antworten!$Z$3:$Z$500,"<>weiß nicht",Antworten!$Z$3:$Z$500,"<>",Antworten!$D$3:$D$500,"Ja") | E43: =COUNTIFS(Antworten!$Z$3:$Z$500,"weiß nicht",Antworten!$D$3:$D$500,"Ja") | F43: =IFERROR(C43/(C43+D43+E43),"")
A44: Gesamt richtig | F44: =IFERROR(SUM(C40:C43)/SUM(C40:E43),"")
...

Sheet Listen
A1: Auswahllisten für die Dropdowns in „Antworten“. Einträge dürfen ergänzt werden (dann Zeilen unten anhängen); Reihenfolge und Schreibweise werden von der Auswertung wörtlich verglichen.
A3: Gültig | B3: Rolle | C3: Altersgruppe | D3: Spielhäufigkeit | E3: Bedienung | F3: Sprache | G3: Letzte Station | H3: Schwierigkeit | I3: Länge | J3: Quiz | K3: Nochmal | L3: Störfaktoren | N3: Quiz-Lösungen | O3: Aussage
A4: Ja | B4: Besucher:in | C4: unter 20 | D4: nie | E4: Tastatur | F4: Deutsch | G4: 1 Stammdaten | H4: zu leicht | I4: zu kurz | J4: richtig | K4: Ja | L4: Steuerung träge | N4: falsch | O4: Q18: Auf der Gesundheitskarte (eGK) sind meine Rezepte gespeichert.
A5: Nein | B5: PwC-Mitarbeiter:in | C5: 20-29 | D5: selten | E5: Arcade-Knöpfe | F5: Englisch | G5: 2 Kartenterminal | H5: genau richtig | I5: genau richtig | J5: falsch | K5: Vielleicht | L5: Zu schwer | N5: richtig | O5: Q19: Die VAU ist ein Raum, in dem im Klartext gearbeitet wird, ohne dass der Betreiber mitliest.
B6: Kunde / Partner | C6: 30-39 | D6: monatlich | E6: Touch | F6: Französisch | G6: 3 KOV Gateway | H6: zu schwer | I6: zu lang | J6: weiß nicht | K6: Nein | L6: Zu leicht | N6: falsch | O6: Q20: Eine abgelaufene Sitzung schützt weiterhin.
B7: Gesundheitswesen | C7: 40-49 | D7: wöchentlich | F7: Spanisch | G7: 4 Die Hülle | L7: Zu viel Text | N7: falsch | O7: Q21: Die Verschlüsselung ersetzt die Unterschrift (Signatur) des Arztes.
B8: Sonstiges | C8: 50-59 | D8: täglich | F8: Chinesisch | G8: 5 Identität | L8: Text zu klein
C9: 60+ | F9: Hindi | G9: 6 E-Rezept | L9: Musik / Klang
G10: 7 Die VAU | L10: Sprachfehler
G11: 8 Kontextschlüssel | L11: Orientierung verloren
G12: 9 Berechtigungen | L12: Technikproblem
G13: 10 Souveränität | L13: Nichts gestört
G14: Reward erreicht

Sheet Antworten
A1: ANTWORTEN — eine Zeile je Person. Gelbe Zellen ausfüllen; Dropdowns über die kleinen Pfeile. „Gültig“ = Ja zählt in der Auswertung. Beispielzeile 3 überschreiben.
A2: Nr | B2: Datum | C2: Erfasst von | D2: Gültig | E2: Rolle | F2: Altersgruppe | G2: Spielhäufigkeit | H2: Vorwissen TI (1-5) | I2: Bedienung | J2: Sprache | K2: Letzte Station | L2: Spielzeit (min) | M2: Spaß (1-5) | N2: Steuerung klar (1-5) | O2: Schwierigkeit passend (1-5) | P2: Orientierung (1-5) | Q2: Briefings hilfreich (1-5) | R2: Texte verständlich (1-5) | S2: Grafik (1-5) | T2: Musik/Klang (1-5) | U2: Schwierigkeit | V2: Länge | W2: Q18 eGK speichert | X2: Q19 VAU = Raum | Y2: Q20 Sitzung abgelaufen | Z2: Q21 Verschl. = Signatur | AA2: Gelernt (1-5) | AB2: Lehrreichste Station | AC2: Störfaktoren (mehrere; durch ; trennen) | AD2: Was hat gefallen? | AE2: Was ändern? | AF2: Weiterempfehlung (0-10) | AG2: Nochmal spielen? | AH2: Bemerkung
A3: 1 | B3: 46272 | C3: A. Muster | D3: Nein | E3: Besucher:in | F3: 30-39 | G3: selten | H3: 2 | I3: Touch | J3: Deutsch | K3: 7 Die VAU | L3: 12 | M3: 4 | N3: 3 | O3: 4 | P3: 3 | Q3: 5 | R3: 4 | S3: 5 | T3: 4 | U3: genau richtig | V3: genau richtig | W3: falsch | X3: richtig | Y3: falsch | Z3: weiß nicht | AA3: 4 | AB3: 7 Die VAU | AC3: Steuerung träge; Text zu klein | AD3: Die Sprechblasen von REZI und die Blende zwischen den Screens. | AE3: Sprung auf Touch fühlt sich verzögert an. | AF3: 8 | AG3: Ja | AH3: Beispielzeile — mit der ersten echten Antwort überschreiben oder Gültig = Nein lassen
